[
  {
    "url": "https://api.github.com/repos/bitcoin/bitcoin/issues/comments/219105087",
    "html_url": "https://github.com/bitcoin/bitcoin/pull/8052#issuecomment-219105087",
    "issue_url": "https://api.github.com/repos/bitcoin/bitcoin/issues/8052",
    "id": 219105087,
    "node_id": "MDEyOklzc3VlQ29tbWVudDIxOTEwNTA4Nw==",
    "user": {
      "login": "jonasschnelli",
      "id": 178464,
      "node_id": "MDQ6VXNlcjE3ODQ2NA==",
      "avatar_url": "https://avatars.githubusercontent.com/u/178464?u=eab5d0cdbb6cc25087cb61d4ca4a6f85255f42a7&v=4",
      "gravatar_id": "",
      "url": "https://api.github.com/users/jonasschnelli",
      "html_url": "https://github.com/jonasschnelli",
      "followers_url": "https://api.github.com/users/jonasschnelli/followers",
      "following_url": "https://api.github.com/users/jonasschnelli/following{/other_user}",
      "gists_url": "https://api.github.com/users/jonasschnelli/gists{/gist_id}",
      "starred_url": "https://api.github.com/users/jonasschnelli/starred{/owner}{/repo}",
      "subscriptions_url": "https://api.github.com/users/jonasschnelli/subscriptions",
      "organizations_url": "https://api.github.com/users/jonasschnelli/orgs",
      "repos_url": "https://api.github.com/users/jonasschnelli/repos",
      "events_url": "https://api.github.com/users/jonasschnelli/events{/privacy}",
      "received_events_url": "https://api.github.com/users/jonasschnelli/received_events",
      "type": "User",
      "site_admin": false
    },
    "created_at": "2016-05-13T17:18:29Z",
    "updated_at": "2016-05-13T17:18:29Z",
    "author_association": "CONTRIBUTOR",
    "body": "Ah. This makes sense!\nFixes #8045 not #8051.\nI could not reproduce #8045 but looks good.\n\nutACK 53bcca971b807b25f219f0aeea25071e38ccea7d\n",
    "reactions": {
      "url": "https://api.github.com/repos/bitcoin/bitcoin/issues/comments/219105087/reactions",
      "total_count": 0,
      "+1": 0,
      "-1": 0,
      "laugh": 0,
      "hooray": 0,
      "confused": 0,
      "heart": 0,
      "rocket": 0,
      "eyes": 0
    },
    "performed_via_github_app": null
  },
  {
    "url": "https://api.github.com/repos/bitcoin/bitcoin/issues/comments/219134037",
    "html_url": "https://github.com/bitcoin/bitcoin/pull/8052#issuecomment-219134037",
    "issue_url": "https://api.github.com/repos/bitcoin/bitcoin/issues/8052",
    "id": 219134037,
    "node_id": "MDEyOklzc3VlQ29tbWVudDIxOTEzNDAzNw==",
    "user": {
      "login": "sipa",
      "id": 548488,
      "node_id": "MDQ6VXNlcjU0ODQ4OA==",
      "avatar_url": "https://avatars.githubusercontent.com/u/548488?u=7999a16349f0df0fb273fffa18e5a955c9d3f11c&v=4",
      "gravatar_id": "",
      "url": "https://api.github.com/users/sipa",
      "html_url": "https://github.com/sipa",
      "followers_url": "https://api.github.com/users/sipa/followers",
      "following_url": "https://api.github.com/users/sipa/following{/other_user}",
      "gists_url": "https://api.github.com/users/sipa/gists{/gist_id}",
      "starred_url": "https://api.github.com/users/sipa/starred{/owner}{/repo}",
      "subscriptions_url": "https://api.github.com/users/sipa/subscriptions",
      "organizations_url": "https://api.github.com/users/sipa/orgs",
      "repos_url": "https://api.github.com/users/sipa/repos",
      "events_url": "https://api.github.com/users/sipa/events{/privacy}",
      "received_events_url": "https://api.github.com/users/sipa/received_events",
      "type": "User",
      "site_admin": false
    },
    "created_at": "2016-05-13T19:11:33Z",
    "updated_at": "2016-05-13T19:11:33Z",
    "author_association": "MEMBER",
    "body": "This does not fix #8045 for me.\n",
    "reactions": {
      "url": "https://api.github.com/repos/bitcoin/bitcoin/issues/comments/219134037/reactions",
      "total_count": 0,
      "+1": 0,
      "-1": 0,
      "laugh": 0,
      "hooray": 0,
      "confused": 0,
      "heart": 0,
      "rocket": 0,
      "eyes": 0
    },
    "performed_via_github_app": null
  },
  {
    "url": "https://api.github.com/repos/bitcoin/bitcoin/issues/comments/219140717",
    "html_url": "https://github.com/bitcoin/bitcoin/pull/8052#issuecomment-219140717",
    "issue_url": "https://api.github.com/repos/bitcoin/bitcoin/issues/8052",
    "id": 219140717,
    "node_id": "MDEyOklzc3VlQ29tbWVudDIxOTE0MDcxNw==",
    "user": {
      "login": "kazcw",
      "id": 1047859,
      "node_id": "MDQ6VXNlcjEwNDc4NTk=",
      "avatar_url": "https://avatars.githubusercontent.com/u/1047859?u=4ae8c609c0f95dec74073fe5f047f8176585a26d&v=4",
      "gravatar_id": "",
      "url": "https://api.github.com/users/kazcw",
      "html_url": "https://github.com/kazcw",
      "followers_url": "https://api.github.com/users/kazcw/followers",
      "following_url": "https://api.github.com/users/kazcw/following{/other_user}",
      "gists_url": "https://api.github.com/users/kazcw/gists{/gist_id}",
      "starred_url": "https://api.github.com/users/kazcw/starred{/owner}{/repo}",
      "subscriptions_url": "https://api.github.com/users/kazcw/subscriptions",
      "organizations_url": "https://api.github.com/users/kazcw/orgs",
      "repos_url": "https://api.github.com/users/kazcw/repos",
      "events_url": "https://api.github.com/users/kazcw/events{/privacy}",
      "received_events_url": "https://api.github.com/users/kazcw/received_events",
      "type": "User",
      "site_admin": false
    },
    "created_at": "2016-05-13T19:41:55Z",
    "updated_at": "2016-05-13T19:48:22Z",
    "author_association": "CONTRIBUTOR",
    "body": "Hm. I can't reliably reproduce the test failure; I got it to happen once by looping `walletbackup.py` until it failed, but the problem's too intermittent here for me to test a solution effectively.\n\nIn the error case, packet capture showed:\nt+0s: `importwallet` request to server\nt+30.5s: FIN+ACK from client\nt+38.5s: reply from server, followed by FIN+ACK from server\n\nSo it looks like it involves a 30 second timeout somewhere on the client end, but since `53bcca9` didn't fix it apparently the problem timeout's value is not originating with `HTTP_TIMEOUT`...\n\n[[I should probably modify this to extend the timeout only for the test case in question, but let's figure out why it isn't working first]]\n",
    "reactions": {
      "url": "https://api.github.com/repos/bitcoin/bitcoin/issues/comments/219140717/reactions",
      "total_count": 0,
      "+1": 0,
      "-1": 0,
      "laugh": 0,
      "hooray": 0,
      "confused": 0,
      "heart": 0,
      "rocket": 0,
      "eyes": 0
    },
    "performed_via_github_app": null
  },
  {
    "url": "https://api.github.com/repos/bitcoin/bitcoin/issues/comments/219143416",
    "html_url": "https://github.com/bitcoin/bitcoin/pull/8052#issuecomment-219143416",
    "issue_url": "https://api.github.com/repos/bitcoin/bitcoin/issues/8052",
    "id": 219143416,
    "node_id": "MDEyOklzc3VlQ29tbWVudDIxOTE0MzQxNg==",
    "user": {
      "login": "sipa",
      "id": 548488,
      "node_id": "MDQ6VXNlcjU0ODQ4OA==",
      "avatar_url": "https://avatars.githubusercontent.com/u/548488?u=7999a16349f0df0fb273fffa18e5a955c9d3f11c&v=4",
      "gravatar_id": "",
      "url": "https://api.github.com/users/sipa",
      "html_url": "https://github.com/sipa",
      "followers_url": "https://api.github.com/users/sipa/followers",
      "following_url": "https://api.github.com/users/sipa/following{/other_user}",
      "gists_url": "https://api.github.com/users/sipa/gists{/gist_id}",
      "starred_url": "https://api.github.com/users/sipa/starred{/owner}{/repo}",
      "subscriptions_url": "https://api.github.com/users/sipa/subscriptions",
      "organizations_url": "https://api.github.com/users/sipa/orgs",
      "repos_url": "https://api.github.com/users/sipa/repos",
      "events_url": "https://api.github.com/users/sipa/events{/privacy}",
      "received_events_url": "https://api.github.com/users/sipa/received_events",
      "type": "User",
      "site_admin": false
    },
    "created_at": "2016-05-13T19:54:18Z",
    "updated_at": "2016-05-13T19:54:18Z",
    "author_association": "MEMBER",
    "body": "I tried with HTTP_TIMEOUT=600, and walletbackup.py still fails reliably. #8051 fixes it.\n",
    "reactions": {
      "url": "https://api.github.com/repos/bitcoin/bitcoin/issues/comments/219143416/reactions",
      "total_count": 0,
      "+1": 0,
      "-1": 0,
      "laugh": 0,
      "hooray": 0,
      "confused": 0,
      "heart": 0,
      "rocket": 0,
      "eyes": 0
    },
    "performed_via_github_app": null
  },
  {
    "url": "https://api.github.com/repos/bitcoin/bitcoin/issues/comments/219144149",
    "html_url": "https://github.com/bitcoin/bitcoin/pull/8052#issuecomment-219144149",
    "issue_url": "https://api.github.com/repos/bitcoin/bitcoin/issues/8052",
    "id": 219144149,
    "node_id": "MDEyOklzc3VlQ29tbWVudDIxOTE0NDE0OQ==",
    "user": {
      "login": "sdaftuar",
      "id": 7463573,
      "node_id": "MDQ6VXNlcjc0NjM1NzM=",
      "avatar_url": "https://avatars.githubusercontent.com/u/7463573?v=4",
      "gravatar_id": "",
      "url": "https://api.github.com/users/sdaftuar",
      "html_url": "https://github.com/sdaftuar",
      "followers_url": "https://api.github.com/users/sdaftuar/followers",
      "following_url": "https://api.github.com/users/sdaftuar/following{/other_user}",
      "gists_url": "https://api.github.com/users/sdaftuar/gists{/gist_id}",
      "starred_url": "https://api.github.com/users/sdaftuar/starred{/owner}{/repo}",
      "subscriptions_url": "https://api.github.com/users/sdaftuar/subscriptions",
      "organizations_url": "https://api.github.com/users/sdaftuar/orgs",
      "repos_url": "https://api.github.com/users/sdaftuar/repos",
      "events_url": "https://api.github.com/users/sdaftuar/events{/privacy}",
      "received_events_url": "https://api.github.com/users/sdaftuar/received_events",
      "type": "User",
      "site_admin": false
    },
    "created_at": "2016-05-13T19:57:31Z",
    "updated_at": "2016-05-13T19:57:31Z",
    "author_association": "MEMBER",
    "body": "Hmm, I think this might be related: https://github.com/bitcoin/bitcoin/pull/6695\n\n@sipa Does it fix it for you if you start bitcoind with a bigger `-rpcservertimeout`?\n",
    "reactions": {
      "url": "https://api.github.com/repos/bitcoin/bitcoin/issues/comments/219144149/reactions",
      "total_count": 0,
      "+1": 0,
      "-1": 0,
      "laugh": 0,
      "hooray": 0,
      "confused": 0,
      "heart": 0,
      "rocket": 0,
      "eyes": 0
    },
    "performed_via_github_app": null
  },
  {
    "url": "https://api.github.com/repos/bitcoin/bitcoin/issues/comments/219145456",
    "html_url": "https://github.com/bitcoin/bitcoin/pull/8052#issuecomment-219145456",
    "issue_url": "https://api.github.com/repos/bitcoin/bitcoin/issues/8052",
    "id": 219145456,
    "node_id": "MDEyOklzc3VlQ29tbWVudDIxOTE0NTQ1Ng==",
    "user": {
      "login": "kazcw",
      "id": 1047859,
      "node_id": "MDQ6VXNlcjEwNDc4NTk=",
      "avatar_url": "https://avatars.githubusercontent.com/u/1047859?u=4ae8c609c0f95dec74073fe5f047f8176585a26d&v=4",
      "gravatar_id": "",
      "url": "https://api.github.com/users/kazcw",
      "html_url": "https://github.com/kazcw",
      "followers_url": "https://api.github.com/users/kazcw/followers",
      "following_url": "https://api.github.com/users/kazcw/following{/other_user}",
      "gists_url": "https://api.github.com/users/kazcw/gists{/gist_id}",
      "starred_url": "https://api.github.com/users/kazcw/starred{/owner}{/repo}",
      "subscriptions_url": "https://api.github.com/users/kazcw/subscriptions",
      "organizations_url": "https://api.github.com/users/kazcw/orgs",
      "repos_url": "https://api.github.com/users/kazcw/repos",
      "events_url": "https://api.github.com/users/kazcw/events{/privacy}",
      "received_events_url": "https://api.github.com/users/kazcw/received_events",
      "type": "User",
      "site_admin": false
    },
    "created_at": "2016-05-13T20:03:23Z",
    "updated_at": "2016-05-13T20:06:49Z",
    "author_association": "CONTRIBUTOR",
    "body": "Oh, the bug in #8051 occurs during send. This fixes a bug in receiving...\n",
    "reactions": {
      "url": "https://api.github.com/repos/bitcoin/bitcoin/issues/comments/219145456/reactions",
      "total_count": 0,
      "+1": 0,
      "-1": 0,
      "laugh": 0,
      "hooray": 0,
      "confused": 0,
      "heart": 0,
      "rocket": 0,
      "eyes": 0
    },
    "performed_via_github_app": null
  },
  {
    "url": "https://api.github.com/repos/bitcoin/bitcoin/issues/comments/219165455",
    "html_url": "https://github.com/bitcoin/bitcoin/pull/8052#issuecomment-219165455",
    "issue_url": "https://api.github.com/repos/bitcoin/bitcoin/issues/8052",
    "id": 219165455,
    "node_id": "MDEyOklzc3VlQ29tbWVudDIxOTE2NTQ1NQ==",
    "user": {
      "login": "sipa",
      "id": 548488,
      "node_id": "MDQ6VXNlcjU0ODQ4OA==",
      "avatar_url": "https://avatars.githubusercontent.com/u/548488?u=7999a16349f0df0fb273fffa18e5a955c9d3f11c&v=4",
      "gravatar_id": "",
      "url": "https://api.github.com/users/sipa",
      "html_url": "https://github.com/sipa",
      "followers_url": "https://api.github.com/users/sipa/followers",
      "following_url": "https://api.github.com/users/sipa/following{/other_user}",
      "gists_url": "https://api.github.com/users/sipa/gists{/gist_id}",
      "starred_url": "https://api.github.com/users/sipa/starred{/owner}{/repo}",
      "subscriptions_url": "https://api.github.com/users/sipa/subscriptions",
      "organizations_url": "https://api.github.com/users/sipa/orgs",
      "repos_url": "https://api.github.com/users/sipa/repos",
      "events_url": "https://api.github.com/users/sipa/events{/privacy}",
      "received_events_url": "https://api.github.com/users/sipa/received_events",
      "type": "User",
      "site_admin": false
    },
    "created_at": "2016-05-13T21:36:58Z",
    "updated_at": "2016-05-13T21:36:58Z",
    "author_association": "MEMBER",
    "body": "@sdaftuar That works!\n",
    "reactions": {
      "url": "https://api.github.com/repos/bitcoin/bitcoin/issues/comments/219165455/reactions",
      "total_count": 0,
      "+1": 0,
      "-1": 0,
      "laugh": 0,
      "hooray": 0,
      "confused": 0,
      "heart": 0,
      "rocket": 0,
      "eyes": 0
    },
    "performed_via_github_app": null
  },
  {
    "url": "https://api.github.com/repos/bitcoin/bitcoin/issues/comments/219269140",
    "html_url": "https://github.com/bitcoin/bitcoin/pull/8052#issuecomment-219269140",
    "issue_url": "https://api.github.com/repos/bitcoin/bitcoin/issues/8052",
    "id": 219269140,
    "node_id": "MDEyOklzc3VlQ29tbWVudDIxOTI2OTE0MA==",
    "user": {
      "login": "MarcoFalke",
      "id": 6399679,
      "node_id": "MDQ6VXNlcjYzOTk2Nzk=",
      "avatar_url": "https://avatars.githubusercontent.com/u/6399679?u=0691974eedcc2ab5366cc1080fb1c030e87244c2&v=4",
      "gravatar_id": "",
      "url": "https://api.github.com/users/MarcoFalke",
      "html_url": "https://github.com/MarcoFalke",
      "followers_url": "https://api.github.com/users/MarcoFalke/followers",
      "following_url": "https://api.github.com/users/MarcoFalke/following{/other_user}",
      "gists_url": "https://api.github.com/users/MarcoFalke/gists{/gist_id}",
      "starred_url": "https://api.github.com/users/MarcoFalke/starred{/owner}{/repo}",
      "subscriptions_url": "https://api.github.com/users/MarcoFalke/subscriptions",
      "organizations_url": "https://api.github.com/users/MarcoFalke/orgs",
      "repos_url": "https://api.github.com/users/MarcoFalke/repos",
      "events_url": "https://api.github.com/users/MarcoFalke/events{/privacy}",
      "received_events_url": "https://api.github.com/users/MarcoFalke/received_events",
      "type": "User",
      "site_admin": false
    },
    "created_at": "2016-05-15T06:31:42Z",
    "updated_at": "2016-05-15T06:31:42Z",
    "author_association": "MEMBER",
    "body": "I tried with HTTP_TIMEOUT=1, and walletbackup.py still works fine.\n",
    "reactions": {
      "url": "https://api.github.com/repos/bitcoin/bitcoin/issues/comments/219269140/reactions",
      "total_count": 0,
      "+1": 0,
      "-1": 0,
      "laugh": 0,
      "hooray": 0,
      "confused": 0,
      "heart": 0,
      "rocket": 0,
      "eyes": 0
    },
    "performed_via_github_app": null
  },
  {
    "url": "https://api.github.com/repos/bitcoin/bitcoin/issues/comments/219291658",
    "html_url": "https://github.com/bitcoin/bitcoin/pull/8052#issuecomment-219291658",
    "issue_url": "https://api.github.com/repos/bitcoin/bitcoin/issues/8052",
    "id": 219291658,
    "node_id": "MDEyOklzc3VlQ29tbWVudDIxOTI5MTY1OA==",
    "user": {
      "login": "kazcw",
      "id": 1047859,
      "node_id": "MDQ6VXNlcjEwNDc4NTk=",
      "avatar_url": "https://avatars.githubusercontent.com/u/1047859?u=4ae8c609c0f95dec74073fe5f047f8176585a26d&v=4",
      "gravatar_id": "",
      "url": "https://api.github.com/users/kazcw",
      "html_url": "https://github.com/kazcw",
      "followers_url": "https://api.github.com/users/kazcw/followers",
      "following_url": "https://api.github.com/users/kazcw/following{/other_user}",
      "gists_url": "https://api.github.com/users/kazcw/gists{/gist_id}",
      "starred_url": "https://api.github.com/users/kazcw/starred{/owner}{/repo}",
      "subscriptions_url": "https://api.github.com/users/kazcw/subscriptions",
      "organizations_url": "https://api.github.com/users/kazcw/orgs",
      "repos_url": "https://api.github.com/users/kazcw/repos",
      "events_url": "https://api.github.com/users/kazcw/events{/privacy}",
      "received_events_url": "https://api.github.com/users/kazcw/received_events",
      "type": "User",
      "site_admin": false
    },
    "created_at": "2016-05-15T15:17:26Z",
    "updated_at": "2016-05-15T15:17:26Z",
    "author_association": "CONTRIBUTOR",
    "body": "This is the error (after `INFO: Restoring using dumped wallet`):\n\n```\nUnexpected exception caught during testing: timeout('timed out',)\n  File \"/bitcoin/qa/rpc-tests/test_framework/test_framework.py\", line 138, in main\n    self.run_test()\n  File \"./walletbackup.py\", line 188, in run_test\n    self.nodes[0].importwallet(tmpdir + \"/node0/wallet.dump\")\n  File \"/bitcoin/qa/rpc-tests/test_framework/coverage.py\", line 49, in __call__\n    return_val = self.auth_service_proxy_instance.__call__(*args, **kwargs)\n  File \"/bitcoin/qa/rpc-tests/test_framework/authproxy.py\", line 137, in __call__\n    response = self._request('POST', self.__url.path, postdata)\n  File \"/bitcoin/qa/rpc-tests/test_framework/authproxy.py\", line 119, in _request\n    return self._get_response()\n  File \"/bitcoin/qa/rpc-tests/test_framework/authproxy.py\", line 152, in _get_response\n    http_response = self.__conn.getresponse()\n  File \"/usr/lib64/python3.4/http/client.py\", line 1171, in getresponse\n    response.begin()\n  File \"/usr/lib64/python3.4/http/client.py\", line 351, in begin\n    version, status, reason = self._read_status()\n  File \"/usr/lib64/python3.4/http/client.py\", line 313, in _read_status\n    line = str(self.fp.readline(_MAXLINE + 1), \"iso-8859-1\")\n  File \"/usr/lib64/python3.4/socket.py\", line 374, in readinto\n    return self._sock.recv_into(b)\nStopping nodes\nWARN: Unable to stop node: CannotSendRequest('Request-sent',)\n```\n\nIt doesn't happen often when my machine is otherwise idle; I looped the test for several hours (originally trying to reproduce the other bug) and got two failures. With the machine under heavy load it happens consistently (all failures look just like the above backtrace).\n\nWhen I set `HTTP_TIMEOUT=1` it fails in an earlier `recv_into` (in various rpc calls).\n",
    "reactions": {
      "url": "https://api.github.com/repos/bitcoin/bitcoin/issues/comments/219291658/reactions",
      "total_count": 0,
      "+1": 0,
      "-1": 0,
      "laugh": 0,
      "hooray": 0,
      "confused": 0,
      "heart": 0,
      "rocket": 0,
      "eyes": 0
    },
    "performed_via_github_app": null
  },
  {
    "url": "https://api.github.com/repos/bitcoin/bitcoin/issues/comments/222693840",
    "html_url": "https://github.com/bitcoin/bitcoin/pull/8052#issuecomment-222693840",
    "issue_url": "https://api.github.com/repos/bitcoin/bitcoin/issues/8052",
    "id": 222693840,
    "node_id": "MDEyOklzc3VlQ29tbWVudDIyMjY5Mzg0MA==",
    "user": {
      "login": "laanwj",
      "id": 126646,
      "node_id": "MDQ6VXNlcjEyNjY0Ng==",
      "avatar_url": "https://avatars.githubusercontent.com/u/126646?u=13b19d1ff2f5f914e180c41418f451a4ba6f8bd1&v=4",
      "gravatar_id": "",
      "url": "https://api.github.com/users/laanwj",
      "html_url": "https://github.com/laanwj",
      "followers_url": "https://api.github.com/users/laanwj/followers",
      "following_url": "https://api.github.com/users/laanwj/following{/other_user}",
      "gists_url": "https://api.github.com/users/laanwj/gists{/gist_id}",
      "starred_url": "https://api.github.com/users/laanwj/starred{/owner}{/repo}",
      "subscriptions_url": "https://api.github.com/users/laanwj/subscriptions",
      "organizations_url": "https://api.github.com/users/laanwj/orgs",
      "repos_url": "https://api.github.com/users/laanwj/repos",
      "events_url": "https://api.github.com/users/laanwj/events{/privacy}",
      "received_events_url": "https://api.github.com/users/laanwj/received_events",
      "type": "User",
      "site_admin": false
    },
    "created_at": "2016-05-31T13:49:26Z",
    "updated_at": "2016-05-31T13:50:18Z",
    "author_association": "MEMBER",
    "body": "As this doesn't fix the issue, we should probably close it?\n\nIf we need this I'd prefer to not change the default value in `authproxy.py` but supply a different timeout where the object is created instead.\n",
    "reactions": {
      "url": "https://api.github.com/repos/bitcoin/bitcoin/issues/comments/222693840/reactions",
      "total_count": 0,
      "+1": 0,
      "-1": 0,
      "laugh": 0,
      "hooray": 0,
      "confused": 0,
      "heart": 0,
      "rocket": 0,
      "eyes": 0
    },
    "performed_via_github_app": null
  },
  {
    "url": "https://api.github.com/repos/bitcoin/bitcoin/issues/comments/223069297",
    "html_url": "https://github.com/bitcoin/bitcoin/pull/8052#issuecomment-223069297",
    "issue_url": "https://api.github.com/repos/bitcoin/bitcoin/issues/8052",
    "id": 223069297,
    "node_id": "MDEyOklzc3VlQ29tbWVudDIyMzA2OTI5Nw==",
    "user": {
      "login": "kazcw",
      "id": 1047859,
      "node_id": "MDQ6VXNlcjEwNDc4NTk=",
      "avatar_url": "https://avatars.githubusercontent.com/u/1047859?u=4ae8c609c0f95dec74073fe5f047f8176585a26d&v=4",
      "gravatar_id": "",
      "url": "https://api.github.com/users/kazcw",
      "html_url": "https://github.com/kazcw",
      "followers_url": "https://api.github.com/users/kazcw/followers",
      "following_url": "https://api.github.com/users/kazcw/following{/other_user}",
      "gists_url": "https://api.github.com/users/kazcw/gists{/gist_id}",
      "starred_url": "https://api.github.com/users/kazcw/starred{/owner}{/repo}",
      "subscriptions_url": "https://api.github.com/users/kazcw/subscriptions",
      "organizations_url": "https://api.github.com/users/kazcw/orgs",
      "repos_url": "https://api.github.com/users/kazcw/repos",
      "events_url": "https://api.github.com/users/kazcw/events{/privacy}",
      "received_events_url": "https://api.github.com/users/kazcw/received_events",
      "type": "User",
      "site_admin": false
    },
    "created_at": "2016-06-01T17:40:49Z",
    "updated_at": "2016-06-01T17:40:49Z",
    "author_association": "CONTRIBUTOR",
    "body": "Yeah, this is too intermittent to worry about; it only came up because I was grinding the test to look for that other bug.\n",
    "reactions": {
      "url": "https://api.github.com/repos/bitcoin/bitcoin/issues/comments/223069297/reactions",
      "total_count": 0,
      "+1": 0,
      "-1": 0,
      "laugh": 0,
      "hooray": 0,
      "confused": 0,
      "heart": 0,
      "rocket": 0,
      "eyes": 0
    },
    "performed_via_github_app": null
  }
]